<?xml version="1.0"?>
<robot xmlns:xacro="https://www.ros.org/wiki/xacro">
    <xacro:include filename="inertial_macros.xacro"/>

    <material name="white">
        <color rgba="1 1 1 1" />
    </material>

    <material name="orange">
        <color rgba="1 0.3 0.1 1"/>
    </material>

    <material name="blue">
        <color rgba="0.2 0.2 1 1"/>
    </material>

    <material name="black">
        <color rgba="0 0 0 1"/>
    </material>

    <link name="base_link">

    </link>

    <joint name="chassis_joint" type="fixed">
        <parent link="base_link"/>
        <child link="chassis"/>
        <origin xyz="0 0 0"/>
    </joint>

    <link name = "chassis">
        <visual>
            <origin xyz="0 0 0.03"/>
            <geometry>
                <box size="0.32 0.15 0.06"/>
            </geometry>
            <material name="white"/>
        </visual>

        <collision>
            <origin xyz="0 0 0.03"/>
            <geometry>
                <box size="0.32 0.15 0.06"/>
            </geometry>
        </collision>

        <xacro:inertial_box mass="0.5" x="0.32" y="0.15" z="0.06">
            <origin xyz="0 0 0.03" rpy="0 0 0"/>
        </xacro:inertial_box>
    </link>

    <joint name="left_wheel_joint" type="continuous">
        <parent link="base_link"/>
        <child link="left_wheel"/>
        <origin xyz="0 0.1 0" rpy="-${pi/2} 0 0"/>
        <axis xyz="0 0 1"/>
    </joint>

    <link name="left_wheel">
        <visual>
            <geometry>
                <cylinder radius="0.0175" length="0.045"/>
            </geometry>
            <material name="blue"/>
        </visual>

        <collision>
            <geometry>
                <cylinder radius="0.0175" length="0.045"/>
            </geometry>
        </collision>

        <xacro:inertial_cylinder mass="0.1" radius="0.0175" length="0.045">
            <origin xyz="0 0 0" rpy="0 0 0"/>
        </xacro:inertial_cylinder>
    </link>

    <joint name="right_wheel_joint" type="continuous">
        <parent link="base_link"/>
        <child link="right_wheel"/>
        <origin xyz="0 -0.1 0" rpy="${pi/2} 0 0"/>
        <axis xyz="0 0 -1"/>
    </joint>

    <link name="right_wheel">
        <visual>
            <geometry>
                <cylinder radius="0.0175" length="0.045"/>
            </geometry>
            <material name="blue"/>
        </visual>

        <collision>
            <geometry>
                <cylinder radius="0.0175" length="0.045"/>
            </geometry>
        </collision>

        <xacro:inertial_cylinder mass="0.1" radius="0.0175" length="0.045">
            <origin xyz="0 0 0" rpy="0 0 0"/>
        </xacro:inertial_cylinder>
    </link>
</robot>